Workbook

Sheet Timeline
A1: S.No | B1: Module | C1: Role | D1: Page | E1: Route | F1: Task to be done | G1: UI improvement | H1: Start date | I1: End date | J1: Window (working days) | K1: Status
A2: 1 | B2: Applicant | C2: Applicant | D2: Application list | E2: applicationform | F2: Show application number, type, status, and last updated date. Make the primary action depend on status: continue draft, view submitted, or open non-compliance. | G2: Align the page title with the new-application button on one row. Show status as a fixed-width badge, and keep row actions on a single line at the right edge of the table. | H2: 46307 | I2: 46307 | J2: =NETWORKDAYS(H2,I2) -> 1 | K2: Not started
A3: 2 | B3: Applicant | C3: Applicant | D3: New application shell | E3: applicationform/addapplicationform | F3: Keep the step list correct for Individual, Firm, Partnership, and Government. Restore the saved step after refresh and block a jump to a step that has no saved parent record. | G3: Lay the stepper out in one line with equal step widths and a clear active step. Pin Back and Next to a bottom bar so they stay in the same place on every step. | H3: 46307 | I3: 46307 | J3: =NETWORKDAYS(H3,I3) -> 1 | K3: Not started
A4: 3 | B4: Applicant | C4: Applicant | D4: Personal details | E4: applicationform/addapplicationform | F4: Validate name, date of birth, PAN, and contact fields. Keep the step label and success or error alert aligned with the application type. | G4: Place the personal-detail fields in a two-column grid with labels directly above each input and equal gaps. Show a field error under that input, and align Save to the right of the form. | H4: 46308 | I4: 46308 | J4: =NETWORKDAYS(H4,I4) -> 1 | K4: Not started
A5: 4 | B5: Applicant | C5: Applicant | D5: Address details | E5: applicationform/addapplicationform | F5: Require address, state, and city from the master lists. Reject an incomplete pin code and keep country, state, and city in a valid chain. | G5: Keep address, country, state, city, and pin code in one aligned grid. Make the dropdowns the same height as the text fields, and keep the error text from pushing the next field out of line. | H5: 46308 | I5: 46308 | J5: =NETWORKDAYS(H5,I5) -> 1 | K5: Not started
A6: 5 | B6: Applicant | C6: Applicant | D6: Financial details | E6: applicationform/addapplicationform | F6: Validate turnover and net-worth figures as numbers, require the supporting period, and show a clear message when a mandatory financial field is missing. | G6: Align amount fields and their labels on one vertical rhythm. Right-align numeric inputs, and keep the helper text directly under the field it describes. | H6: 46309 | I6: 46309 | J6: =NETWORKDAYS(H6,I6) -> 1 | K6: Not started
A7: 6 | B7: Applicant | C7: Applicant | D7: Additional details | E7: applicationform/addapplicationform | F7: Make every required question answerable, keep remarks mandatory where the answer needs an explanation, and preserve answers when the user moves back a step. | G7: Give each question the same spacing and a full-width answer control. Keep radio or checkbox options in a straight row, and place any remark box under the question that needs it. | H7: 46309 | I7: 46309 | J7: =NETWORKDAYS(H7,I7) -> 1 | K7: Not started
A8: 7 | B8: Applicant | C8: Applicant | D8: Firm details | E8: applicationform/addapplicationform | F8: Show this step only for firm and partnership types. Validate firm name, registration, and date of incorporation, and reject a future incorporation date. | G8: Group firm name, registration, and dates into one card with a visible heading. Keep date fields the same width, and align the action buttons with the other application steps. | H8: 46310 | I8: 46310 | J8: =NETWORKDAYS(H8,I8) -> 1 | K8: Not started
A9: 8 | B9: Applicant | C9: Applicant | D9: Income-tax documents | E9: applicationform/addapplicationform | F9: Restrict uploads to the allowed file types and size, require the assessment year, and let the user replace a file without leaving a broken document reference. | G9: Show each upload as a row with the document name, file name, and a replace action lined up in columns. Give the empty upload a clear drop area instead of a bare file input. | H9: 46310 | I9: 46310 | J9: =NETWORKDAYS(H9,I9) -> 1 | K9: Not started
A10: 9 | B10: Applicant | C10: Applicant | D10: Partner details | E10: applicationform/addapplicationform | F10: Require at least one partner for partnership applications. Validate each partner's identity fields and stop a blank partner row from being saved. | G10: Show partners as separate cards with the same internal field grid. Line up Add partner and Remove so they do not sit at different heights when a validation message appears. | H10: 46311 | I10: 46311 | J10: =NETWORKDAYS(H10,I10) -> 1 | K10: Not started
A11: 10 | B11: Applicant | C11: Applicant | D11: Authorized representative | E11: applicationform/addapplicationform | F11: Validate representative name, designation, and contact details. Keep the authorization document required before the step can be completed. | G11: Align the representative fields and the authorization upload on the same form grid. Keep the file name visible beside the upload button after a file is chosen. | H11: 46311 | I11: 46311 | J11: =NETWORKDAYS(H11,I11) -> 1 | K11: Not started
A12: 11 | B12: Applicant | C12: Applicant | D12: Organizational details | E12: applicationform/addapplicationform | F12: Show this step for government applications. Require organization name, ministry or department, and the authorized contact before save. | G12: Use one section heading and a single-column stack for organization, department, and contact. Match the input height and button placement used on the other government steps. | H12: 46314 | I12: 46314 | J12: =NETWORKDAYS(H12,I12) -> 1 | K12: Not started
A13: 12 | B13: Applicant | C13: Applicant | D13: Location of facility | E13: applicationform/addapplicationform | F13: Require at least one facility address. Validate city and state against masters and keep multiple locations editable without losing earlier rows. | G13: Show each facility as a card with address fields in a consistent grid. Keep Add location at the bottom left and the step actions at the bottom right. | H13: 46315 | I13: 46315 | J13: =NETWORKDAYS(H13,I13) -> 1 | K13: Not started
A14: 13 | B14: Applicant | C14: Applicant | D14: CPS and additional documents | E14: applicationform/addapplicationform | F14: Load the CPS document list from the master, mark mandatory documents, and block continue while a required file is missing or still uploading. | G14: List each CPS document in a table-like row: name, required marker, file, and action. Mark missing required files in the row itself so the gap is visible without scrolling to an alert. | H14: 46315 | I14: 46315 | J14: =NETWORKDAYS(H14,I14) -> 1 | K14: Not started
A15: 14 | B15: Applicant | C15: Applicant | D15: Individual checklist | E15: applicationform/addapplicationform | F15: Match checklist points to the individual application type. Require every point to be accepted before declaration. | G15: Show checklist points as a single column with the checkbox and the point text vertically centered. Keep the accept control from wrapping onto a second uneven line. | H15: 46316 | I15: 46316 | J15: 2 | K15: Not started
A16: 15 | B16: Applicant | C16: Applicant | D16: Firm checklist and declaration | E16: applicationform/addapplicationform | F16: Use the firm or partnership checklist, require the declaration text to be accepted, and keep the signatory name consistent with the saved representative. | G16: Separate the checklist and the declaration into two stacked sections with the same left margin. Make the declaration text readable, and place the acceptance checkbox on its own row above the buttons. | H16: 46316 | I16: 46316 | J16: 2 | K16: Not started
A17: 16 | B17: Applicant | C17: Applicant | D17: Government checklist and declaration | E17: applicationform/addapplicationform | F17: Use the government declaration wording and block submit until the organizational details and declaration are both complete. | G17: Use the same checklist spacing as the other declarations. Keep the government declaration block full width and the acceptance checkbox aligned with the first line of that text. | H17: 46316 | I17: 46316 | J17: 2 | K17: Not started
A18: 17 | B18: Applicant | C18: Applicant | D18: Submit preview | E18: applicationform/addapplicationform | F18: Show a read-only summary of every saved step. Final submit must use the final-submission message and return the user to the application list with status updated. | G18: Present the preview as labeled sections in the same order as the wizard. Use a definition layout for values, and put Edit and Submit on one button row at the bottom. | H18: 46316 | I18: 46316 | J18: 2 | K18: Not started
A19: 18 | B19: Applicant | C19: Applicant | D19: Application view | E19: applicationform | F19: Open a submitted application in read-only form for individual, firm, and government, with the same field labels used on the edit steps. | G19: Use the same section headings and two-column value layout for individual, firm, and government views. Keep long values from overflowing the card, and show document names as consistent links. | H19: 46317 | I19: 46317 | J19: 2 | K19: Not started
A20: 19 | B20: Applicant | C20: Applicant | D20: Non-compliance response | E20: applicationform/auditordetails/:id | F20: List auditor remarks, require the applicant's reply and evidence where a point is open, and keep closed points read-only. | G20: Show each remark as a card: finding, reply field, and evidence upload stacked with equal padding. Visually mute closed points so open points are the ones that stand out. | H20: 46317 | I20: 46317 | J20: =NETWORKDAYS(H20,I20) -> 1 | K20: Not started
A21: 20 | B21: Applicant | C21: Applicant | D21: Application audit controls | E21: applicationform/applicationauditordetails/:id | F21: Show each control with its result and the applicant action. Save a reply without clearing other controls on the same page. | G21: Put control text, result, and the reply on one aligned row. Keep the result control a fixed width so the reply field does not jump between rows. | H21: 46317 | I21: 46317 | J21: =NETWORKDAYS(H21,I21) -> 1 | K21: Not started
A22: 21 | B22: Applicant | C22: Applicant | D22: Select audit agency | E22: applicationform/selectauditagency/:id | F22: List only active audit agencies, confirm the selection, and prevent a second selection after one is already submitted. | G22: Show agencies as equal-height selectable cards or a clean table with one radio per row. Make the selected row obvious, and place Confirm on the right of the page footer. | H22: 46318 | I22: 46318 | J22: =NETWORKDAYS(H22,I22) -> 1 | K22: Not started
A23: 22 | B23: Applicant | C23: Applicant | D23: Payment proof | E23: applicationform/addapplicationform | F23: Require payment mode, reference, date, and proof file. Reject a future payment date and show the uploaded proof name after save. | G23: Align mode, reference, date, and the proof upload in one grid. Show the chosen file name under the upload control, and keep the date field the same width as the other inputs. | H23: 46318 | I23: 46318 | J23: =NETWORKDAYS(H23,I23) -> 1 | K23: Not started
A24: 23 | B24: Applicant | C24: Applicant | D24: Annexure A2 Home | E24: applicationform/selectauditagency/:id | F24: Open the annexure shell, show completion status per section, and block final submit until required sections are saved. | G24: On the applicant annexure, show the annexure title and a section list as equal rows with a completion mark on the left and the section name on one line. Keep the continue action in a footer. | H24: 46321 | I24: 46322 | J24: 2 | K24: Not started
A25: 24 | B25: Applicant | C25: Applicant | D25: CA Details | E25: applicationform/selectauditagency/:id | F25: Validate CA identity fields, licence number format, and required contact details before save. | G25: On the applicant annexure, lay identity and contact fields in a two-column grid with labels above the inputs. Keep licence number on its own row so it stays readable. | H25: 46321 | I25: 46322 | J25: 2 | K25: Not started
A26: 25 | B26: Applicant | C26: Applicant | D26: CA Service Details | E26: applicationform/selectauditagency/:id | F26: Keep selected services in sync with the licence, and stop empty or duplicate service rows. | G26: On the applicant annexure, show services as aligned rows with the service name and a remove action on the same baseline. Place Add service at the left of the section footer. | H26: 46321 | I26: 46322 | J26: 2 | K26: Not started
A27: 26 | B27: Applicant | C27: Applicant | D27: CA Self Assessment | E27: applicationform/selectauditagency/:id | F27: Require an answer for every assessment point and keep remarks mandatory when the answer is negative. | G27: On the applicant annexure, give every assessment point the same row height, with the answer control in a fixed column and the remark box full width under a negative answer. | H27: 46321 | I27: 46322 | J27: 2 | K27: Not started
A28: 27 | B28: Applicant | C28: Applicant | D28: Data Centre Details | E28: applicationform/selectauditagency/:id | F28: Validate site address, city, and capacity fields, and allow more than one centre without losing earlier rows. | G28: On the applicant annexure, show each centre as a card with the address grid inside. Keep Add centre outside the cards so it does not move when a card grows. | H28: 46321 | I28: 46322 | J28: 2 | K28: Not started
A29: 28 | B29: Applicant | C29: Applicant | D29: Trusted Persons List | E29: applicationform/selectauditagency/:id | F29: Validate person name, role, and identity fields, and prevent a blank row from being saved. | G29: On the applicant annexure, show people in a table or equal cards with name, role, and identity in fixed columns. Keep add and remove actions aligned. | H29: 46321 | I29: 46322 | J29: 2 | K29: Not started
A30: 29 | B30: Applicant | C30: Applicant | D30: ASP Details | E30: applicationform/selectauditagency/:id | F30: Validate ASP name and agreement dates, and reject an end date that falls before the start date. | G30: On the applicant annexure, align ASP name and the two agreement dates on one grid. Keep the date fields equal width and side by side. | H30: 46321 | I30: 46322 | J30: 2 | K30: Not started
A31: 30 | B31: Applicant | C31: Applicant | D31: Audit Details | E31: applicationform/selectauditagency/:id | F31: Capture audit period, agency, and outcome with required fields and a clear save confirmation. | G31: On the applicant annexure, group period, agency, and outcome in one card. Place the save confirmation area under the card, not as a floating message over the fields. | H31: 46321 | I31: 46322 | J31: 2 | K31: Not started
A32: 31 | B32: Applicant | C32: Applicant | D32: Internal Audit Details | E32: applicationform/selectauditagency/:id | F32: Require auditor name, period, and finding summary, and show a friendly error when save fails. | G32: On the applicant annexure, stack auditor, period, and finding summary with the summary full width. Match the field spacing used on Audit Details. | H32: 46321 | I32: 46322 | J32: 2 | K32: Not started
A33: 32 | B33: Applicant | C33: Applicant | D33: eKYC Audit Details | E33: applicationform/selectauditagency/:id | F33: Validate mode, volume, and exception counts, and reject non-numeric values in count fields. | G33: On the applicant annexure, right-align the count fields and keep mode, volume, and exceptions on one row on a wide screen. Keep labels from colliding with the inputs. | H33: 46321 | I33: 46322 | J33: 2 | K33: Not started
A34: 33 | B34: Applicant | C34: Applicant | D34: eKYC Verification Details | E34: applicationform/selectauditagency/:id | F34: Keep verification method and sample size required, and preserve entered values after a validation error. | G34: On the applicant annexure, align method and sample size on one row. Keep any error text under its own field so the row above does not jump. | H34: 46321 | I34: 46322 | J34: 2 | K34: Not started
A35: 34 | B35: Applicant | C35: Applicant | D35: Crypto Token Empanelment | E35: applicationform/selectauditagency/:id | F35: Validate token provider, approval status, and supporting reference before the section can be marked complete. | G35: On the applicant annexure, place provider, approval status, and reference in one card. Show approval status as a dropdown the same height as the text fields. | H35: 46321 | I35: 46322 | J35: 2 | K35: Not started
... A42: 41 | B42: Applicant | C42: Applicant | D42: RA Audit Details | E42: applicationform/selectauditagency/:id | F42: Validate registration authority name, audit period, and result, and show the saved summary on return to the section. | G42: On the applicant annexure, align authority name, period, and result on one card, and show the saved summary as a quiet line under the card. | H42: 46321 | I42: 46322 | J42: 2 | K42: Not started
A43: 42 | B43: Licensee | C43: Licensee | D43: View licence | E43: viewlicense | F43: Show licence number, validity, services, and the actions still open: renewal, cessation, eSign application, and annual audit. | G43: Show licence number, validity, and services in a summary strip at the top. Place renewal, cessation, eSign, and audit actions as equal buttons that wrap cleanly instead of overflowing. | H43: 46323 | I43: 46323 | J43: =NETWORKDAYS(H43,I43) -> 1 | K43: Not started
A44: 43 | B44: Licensee | C44: Licensee | D44: Renewal application list | E44: renewallicense | F44: Show renewal drafts and submitted renewals with status, and open the correct next step from each row. | G44: Match the new-application list: title and action on one row, status badge, and row actions aligned to the right. Keep renewal status labels from wrapping inside the badge. | H44: 46323 | I44: 46323 | J44: =NETWORKDAYS(H44,I44) -> 1 | K44: Not started
A45: 44 | B45: Licensee | C45: Licensee | D45: Renewal wizard | E45: renewallicense/renewallicenses | F45: Reuse the new-application step order for the licence type, and prefill fields from the current licence without letting stale draft data overwrite them silently. | G45: Reuse the same stepper, step spacing, and bottom button bar as the new-application wizard so the two flows look like one product. | H45: 46323 | I45: 46323 | J45: =NETWORKDAYS(H45,I45) -> 1 | K45: Not started
A46: 45 | B46: Licensee | C46: Licensee | D46: Renewal personal and address details | E46: renewallicense/renewallicenses | F46: Prefill personal and address data, validate edits the same way as a new application, and keep unchanged fields from being marked as missing. | G46: Use the same two-column grid as personal and address on a new application. Show prefilled values in the same input style, and keep edited and untouched fields visually identical. | H46: 46324 | I46: 46324 | J46: 2 | K46: Not started
...

Sheet Module summary
A1: Module | B1: Role | C1: Pages | D1: Start | E1: End | F1: Not started | G1: In progress | H1: Blocked | I1: Done
A2: Applicant | B2: Applicant | C2: =COUNTIFS(Timeline!B:B,A2,Timeline!C:C,B2) -> 41 | F2: =COUNTIFS(Timeline!B:B,A2,Timeline!C:C,B2,Timeline!K:K,"Not started") -> 41 | G2: =COUNTIFS(Timeline!B:B,A2,Timeline!C:C,B2,Timeline!K:K,"In progress") -> 0 | H2: =COUNTIFS(Timeline!B:B,A2,Timeline!C:C,B2,Timeline!K:K,"Blocked") -> 0 | I2: =COUNTIFS(Timeline!B:B,A2,Timeline!C:C,B2,Timeline!K:K,"Done") -> 0
A3: Licensee | B3: Licensee | C3: =COUNTIFS(Timeline!B:B,A3,Timeline!C:C,B3) -> 41 | F3: =COUNTIFS(Timeline!B:B,A3,Timeline!C:C,B3,Timeline!K:K,"Not started") -> 41 | G3: =COUNTIFS(Timeline!B:B,A3,Timeline!C:C,B3,Timeline!K:K,"In progress") -> 0 | H3: =COUNTIFS(Timeline!B:B,A3,Timeline!C:C,B3,Timeline!K:K,"Blocked") -> 0 | I3: =COUNTIFS(Timeline!B:B,A3,Timeline!C:C,B3,Timeline!K:K,"Done") -> 0
A4: Office of CCA | B4: CCA Officer | C4: =COUNTIFS(Timeline!B:B,A4,Timeline!C:C,B4) -> 13 | F4: =COUNTIFS(Timeline!B:B,A4,Timeline!C:C,B4,Timeline!K:K,"Not started") -> 13 | G4: =COUNTIFS(Timeline!B:B,A4,Timeline!C:C,B4,Timeline!K:K,"In progress") -> 0 | H4: =COUNTIFS(Timeline!B:B,A4,Timeline!C:C,B4,Timeline!K:K,"Blocked") -> 0 | I4: =COUNTIFS(Timeline!B:B,A4,Timeline!C:C,B4,Timeline!K:K,"Done") -> 0
A5: Review committee | B5: Review committee | C5: =COUNTIFS(Timeline!B:B,A5,Timeline!C:C,B5) -> 12 | F5: =COUNTIFS(Timeline!B:B,A5,Timeline!C:C,B5,Timeline!K:K,"Not started") -> 12 | G5: =COUNTIFS(Timeline!B:B,A5,Timeline!C:C,B5,Timeline!K:K,"In progress") -> 0 | H5: =COUNTIFS(Timeline!B:B,A5,Timeline!C:C,B5,Timeline!K:K,"Blocked") -> 0 | I5: =COUNTIFS(Timeline!B:B,A5,Timeline!C:C,B5,Timeline!K:K,"Done") -> 0
A6: CCA | B6: CCA | C6: =COUNTIFS(Timeline!B:B,A6,Timeline!C:C,B6) -> 34 | F6: =COUNTIFS(Timeline!B:B,A6,Timeline!C:C,B6,Timeline!K:K,"Not started") -> 34 | G6: =COUNTIFS(Timeline!B:B,A6,Timeline!C:C,B6,Timeline!K:K,"In progress") -> 0 | H6: =COUNTIFS(Timeline!B:B,A6,Timeline!C:C,B6,Timeline!K:K,"Blocked") -> 0 | I6: =COUNTIFS(Timeline!B:B,A6,Timeline!C:C,B6,Timeline!K:K,"Done") -> 0
A7: Audit agency | B7: Audit agency | C7: =COUNTIFS(Timeline!B:B,A7,Timeline!C:C,B7) -> 34 | F7: =COUNTIFS(Timeline!B:B,A7,Timeline!C:C,B7,Timeline!K:K,"Not started") -> 34 | G7: =COUNTIFS(Timeline!B:B,A7,Timeline!C:C,B7,Timeline!K:K,"In progress") -> 0 | H7: =COUNTIFS(Timeline!B:B,A7,Timeline!C:C,B7,Timeline!K:K,"Blocked") -> 0 | I7: =COUNTIFS(Timeline!B:B,A7,Timeline!C:C,B7,Timeline!K:K,"Done") -> 0
A8: Dashboards | B8: CCA | C8: =COUNTIFS(Timeline!B:B,A8,Timeline!C:C,B8) -> 5 | F8: =COUNTIFS(Timeline!B:B,A8,Timeline!C:C,B8,Timeline!K:K,"Not started") -> 5 | G8: =COUNTIFS(Timeline!B:B,A8,Timeline!C:C,B8,Timeline!K:K,"In progress") -> 0 | H8: =COUNTIFS(Timeline!B:B,A8,Timeline!C:C,B8,Timeline!K:K,"Blocked") -> 0 | I8: =COUNTIFS(Timeline!B:B,A8,Timeline!C:C,B8,Timeline!K:K,"Done") -> 0
A9: Dashboards | B9: CCA Officer | C9: =COUNTIFS(Timeline!B:B,A9,Timeline!C:C,B9) -> 1 | F9: =COUNTIFS(Timeline!B:B,A9,Timeline!C:C,B9,Timeline!K:K,"Not started") -> 1 | G9: =COUNTIFS(Timeline!B:B,A9,Timeline!C:C,B9,Timeline!K:K,"In progress") -> 0 | H9: =COUNTIFS(Timeline!B:B,A9,Timeline!C:C,B9,Timeline!K:K,"Blocked") -> 0 | I9: =COUNTIFS(Timeline!B:B,A9,Timeline!C:C,B9,Timeline!K:K,"Done") -> 0
A10: Dashboards | B10: Admin | C10: =COUNTIFS(Timeline!B:B,A10,Timeline!C:C,B10) -> 1 | F10: =COUNTIFS(Timeline!B:B,A10,Timeline!C:C,B10,Timeline!K:K,"Not started") -> 1 | G10: =COUNTIFS(Timeline!B:B,A10,Timeline!C:C,B10,Timeline!K:K,"In progress") -> 0 | H10: =COUNTIFS(Timeline!B:B,A10,Timeline!C:C,B10,Timeline!K:K,"Blocked") -> 0 | I10: =COUNTIFS(Timeline!B:B,A10,Timeline!C:C,B10,Timeline!K:K,"Done") -> 0
A11: Operations data | B11: Licensee | C11: =COUNTIFS(Timeline!B:B,A11,Timeline!C:C,B11) -> 6 | F11: =COUNTIFS(Timeline!B:B,A11,Timeline!C:C,B11,Timeline!K:K,"Not started") -> 6 | G11: =COUNTIFS(Timeline!B:B,A11,Timeline!C:C,B11,Timeline!K:K,"In progress") -> 0 | H11: =COUNTIFS(Timeline!B:B,A11,Timeline!C:C,B11,Timeline!K:K,"Blocked") -> 0 | I11: =COUNTIFS(Timeline!B:B,A11,Timeline!C:C,B11,Timeline!K:K,"Done") -> 0
A12: Reports | B12: CCA Officer | C12: =COUNTIFS(Timeline!B:B,A12,Timeline!C:C,B12) -> 18 | F12: =COUNTIFS(Timeline!B:B,A12,Timeline!C:C,B12,Timeline!K:K,"Not started") -> 18 | G12: =COUNTIFS(Timeline!B:B,A12,Timeline!C:C,B12,Timeline!K:K,"In progress") -> 0 | H12: =COUNTIFS(Timeline!B:B,A12,Timeline!C:C,B12,Timeline!K:K,"Blocked") -> 0 | I12: =COUNTIFS(Timeline!B:B,A12,Timeline!C:C,B12,Timeline!K:K,"Done") -> 0
A13: Admin masters | B13: Admin | C13: =COUNTIFS(Timeline!B:B,A13,Timeline!C:C,B13) -> 89 | F13: =COUNTIFS(Timeline!B:B,A13,Timeline!C:C,B13,Timeline!K:K,"Not started") -> 89 | G13: =COUNTIFS(Timeline!B:B,A13,Timeline!C:C,B13,Timeline!K:K,"In progress") -> 0 | H13: =COUNTIFS(Timeline!B:B,A13,Timeline!C:C,B13,Timeline!K:K,"Blocked") -> 0 | I13: =COUNTIFS(Timeline!B:B,A13,Timeline!C:C,B13,Timeline!K:K,"Done") -> 0
A14: Total | C14: =SUM(C2:C13) -> 295 | F14: =SUM(F2:F13) -> 295 | G14: =SUM(G2:G13) -> 0 | H14: =SUM(H2:H13) -> 0 | I14: =SUM(I2:I13) -> 0
